Workbook

Sheet Dataset
A1: Transaction_ID | B1: Date | C1: Customer_ID | D1: Customer_Name | E1: Product_ID | F1: Product_Name | G1: Category | H1: Quantity | I1: Unit_Price | J1: Payment_Method | K1: Region | L1: Customer_Segment | M1: Customer_Since | N1: Total_Amount | O1: Current date | P1: Current timestamp | Q1: Customer tenure in years | R1: Customer Tenure in month | S1: End of transaction Month | T1: Product Abbrevation
A2: TRX0155 | B2: 45393 | C2: CUST023 | D2: Paul Baker | E2: P009 | F2: Monitor | G2: Electronics | H2: 3 | I2: 249.99 | J2: Cash | K2: Central | L2: Basic | M2: 44425 | N2: 749.97 | O2: =TODAY() -> 46312 | P2: =NOW() -> 46312.461 | Q2: =DATEDIF(M2,TODAY(),"Y") -> 5 | R2: =DATEDIF(M2,TODAY(),"M") -> 62 | S2: =EOMONTH(B2,0) -> 45412 | T2: =CONCATENATE(LEFT(G2,5),"-",LEFT(F2,4),"-",E2) -> Elect-Moni-P009
A3: TRX0023 | B3: 45396 | C3: CUST013 | D3: Joseph Jackson | E3: P009 | F3: Monitor | G3: Electronics | H3: 3 | I3: 249.99 | J3: Credit Card | K3: Central | L3: Premium | M3: 44575 | N3: 749.97 | O3: =TODAY() -> 46312 | P3: =NOW() -> 46312.461 | Q3: =DATEDIF(M3,TODAY(),"Y") -> 4 | R3: =DATEDIF(M3,TODAY(),"M") -> 57 | S3: =EOMONTH(B3,0) -> 45412 | T3: =CONCATENATE(LEFT(G3,5),"-",LEFT(F3,4),"-",E3) -> Elect-Moni-P009
A4: TRX0139 | B4: 45399 | C4: CUST021 | D4: Kevin Scott | E4: P005 | F4: Blender | G4: Appliances | H4: 3 | I4: 59.99 | J4: PayPal | K4: South | L4: Standard | M4: 45262 | N4: 179.97 | O4: =TODAY() -> 46312 | P4: =NOW() -> 46312.461 | Q4: =DATEDIF(M4,TODAY(),"Y") -> 2 | R4: =DATEDIF(M4,TODAY(),"M") -> 34 | S4: =EOMONTH(B4,0) -> 45412 | T4: =CONCATENATE(LEFT(G4,5),"-",LEFT(F4,4),"-",E4) -> Appli-Blen-P005
A5: TRX0043 | B5: 45400 | C5: CUST046 | D5: Kathleen Bennett | E5: P005 | F5: Blender | G5: Appliances | H5: 3 | I5: 59.99 | J5: Cash | K5: North | L5: Premium | M5: 45114 | N5: 179.97 | O5: =TODAY() -> 46312 | P5: =NOW() -> 46312.461 | Q5: =DATEDIF(M5,TODAY(),"Y") -> 3 | R5: =DATEDIF(M5,TODAY(),"M") -> 39 | S5: =EOMONTH(B5,0) -> 45412 | T5: =CONCATENATE(LEFT(G5,5),"-",LEFT(F5,4),"-",E5) -> Appli-Blen-P005
A6: TRX0212 | B6: 45400 | C6: CUST003 | D6: Michael Brown | E6: P008 | F6: Bookshelf | G6: Furniture | H6: 5 | I6: 149.99 | J6: Credit Card | K6: North | L6: Premium | M6: 45295 | N6: 749.95 | O6: =TODAY() -> 46312 | P6: =NOW() -> 46312.461 | Q6: =DATEDIF(M6,TODAY(),"Y") -> 2 | R6: =DATEDIF(M6,TODAY(),"M") -> 33 | S6: =EOMONTH(B6,0) -> 45412 | T6: =CONCATENATE(LEFT(G6,5),"-",LEFT(F6,4),"-",E6) -> Furni-Book-P008
A7: TRX0092 | B7: 45403 | C7: CUST024 | D7: Dorothy Nelson | E7: P005 | F7: Blender | G7: Appliances | H7: 2 | I7: 59.99 | J7: Cash | K7: West | L7: Standard | M7: 44746 | N7: 119.98 | O7: =TODAY() -> 46312 | P7: =NOW() -> 46312.461 | Q7: =DATEDIF(M7,TODAY(),"Y") -> 4 | R7: =DATEDIF(M7,TODAY(),"M") -> 51 | S7: =EOMONTH(B7,0) -> 45412 | T7: =CONCATENATE(LEFT(G7,5),"-",LEFT(F7,4),"-",E7) -> Appli-Blen-P005
A8: TRX0193 | B8: 45403 | C8: CUST024 | D8: Dorothy Nelson | E8: P003 | F8: Headphones | G8: Electronics | H8: 5 | I8: 149.99 | J8: Credit Card | K8: Central | L8: Standard | M8: 44418 | N8: 749.95 | O8: =TODAY() -> 46312 | P8: =NOW() -> 46312.461 | Q8: =DATEDIF(M8,TODAY(),"Y") -> 5 | R8: =DATEDIF(M8,TODAY(),"M") -> 62 | S8: =EOMONTH(B8,0) -> 45412 | T8: =CONCATENATE(LEFT(G8,5),"-",LEFT(F8,4),"-",E8) -> Elect-Head-P003
A9: TRX0240 | B9: 45403 | C9: CUST017 | D9: Charles Allen | E9: P005 | F9: Blender | G9: Appliances | H9: 3 | I9: 59.99 | J9: Debit Card | K9: South | L9: Basic | M9: 45007 | N9: 179.97 | O9: =TODAY() -> 46312 | P9: =NOW() -> 46312.461 | Q9: =DATEDIF(M9,TODAY(),"Y") -> 3 | R9: =DATEDIF(M9,TODAY(),"M") -> 42 | S9: =EOMONTH(B9,0) -> 45412 | T9: =CONCATENATE(LEFT(G9,5),"-",LEFT(F9,4),"-",E9) -> Appli-Blen-P005
A10: TRX0135 | B10: 45405 | C10: CUST009 | D10: Robert Thomas | E10: P001 | F10: Laptop | G10: Electronics | H10: 3 | I10: 899.99 | J10: PayPal | K10: East | L10: Standard | M10: 45299 | N10: 2699.97 | O10: =TODAY() -> 46312 | P10: =NOW() -> 46312.461 | Q10: =DATEDIF(M10,TODAY(),"Y") -> 2 | R10: =DATEDIF(M10,TODAY(),"M") -> 33 | S10: =EOMONTH(B10,0) -> 45412 | T10: =CONCATENATE(LEFT(G10,5),"-",LEFT(F10,4),"-",E10) -> Elect-Lapt-P001
A11: TRX0185 | B11: 45408 | C11: CUST026 | D11: Karen Hill | E11: P005 | F11: Blender | G11: Appliances | H11: 3 | I11: 59.99 | J11: Cash | K11: West | L11: Premium | M11: 45207 | N11: 179.97 | O11: =TODAY() -> 46312 | P11: =NOW() -> 46312.461 | Q11: =DATEDIF(M11,TODAY(),"Y") -> 3 | R11: =DATEDIF(M11,TODAY(),"M") -> 36 | S11: =EOMONTH(B11,0) -> 45412 | T11: =CONCATENATE(LEFT(G11,5),"-",LEFT(F11,4),"-",E11) -> Appli-Blen-P005
A12: TRX0138 | B12: 45408 | C12: CUST022 | D12: Susan Green | E12: P008 | F12: Bookshelf | G12: Furniture | H12: 1 | I12: 149.99 | J12: Credit Card | K12: West | L12: Standard | M12: 45103 | N12: 149.99 | O12: =TODAY() -> 46312 | P12: =NOW() -> 46312.461 | Q12: =DATEDIF(M12,TODAY(),"Y") -> 3 | R12: =DATEDIF(M12,TODAY(),"M") -> 39 | S12: =EOMONTH(B12,0) -> 45412 | T12: =CONCATENATE(LEFT(G12,5),"-",LEFT(F12,4),"-",E12) -> Furni-Book-P008
A13: TRX0209 | B13: 45408 | C13: CUST046 | D13: Kathleen Bennett | E13: P008 | F13: Bookshelf | G13: Furniture | H13: 5 | I13: 149.99 | J13: Debit Card | K13: North | L13: Basic | M13: 44830 | N13: 749.95 | O13: =TODAY() -> 46312 | P13: =NOW() -> 46312.461 | Q13: =DATEDIF(M13,TODAY(),"Y") -> 4 | R13: =DATEDIF(M13,TODAY(),"M") -> 48 | S13: =EOMONTH(B13,0) -> 45412 | T13: =CONCATENATE(LEFT(G13,5),"-",LEFT(F13,4),"-",E13) -> Furni-Book-P008
... A251: TRX0064 | B251: 45758 | C251: CUST031 | D251: Steven Turner | E251: P010 | F251: Keyboard | G251: Electronics | H251: 3 | I251: 89.99 | J251: Debit Card | K251: North | L251: Premium | M251: 44878 | N251: 269.97 | O251: =TODAY() -> 46312 | P251: =NOW() -> 46312.461 | Q251: =DATEDIF(M251,TODAY(),"Y") -> 3 | R251: =DATEDIF(M251,TODAY(),"M") -> 47 | S251: =EOMONTH(B251,0) -> 45777 | T251: =CONCATENATE(LEFT(G251,5),"-",LEFT(F251,4),"-",E251) -> Elect-Keyb-P010

Sheet Analysis & Calculation
A1: Filter transaction for "Electronics" category and "North" region | P1: Filter transaction Greater than 1500 | AE1: Filtering payment method == "Cash" | AT1: Filtering Payment method== Credit Card and Customer Segment == Premium
A2: Transaction_ID | B2: Date | C2: Customer_ID | D2: Customer_Name | E2: Product_ID | F2: Product_Name | G2: Category | H2: Quantity | I2: Unit_Price | J2: Payment_Method | K2: Region | L2: Customer_Segment | M2: Customer_Since | N2: Total_Amount | P2: Transaction_ID | Q2: Date | R2: Customer_ID | S2: Customer_Name | T2: Product_ID | U2: Product_Name | V2: Category | W2: Quantity | X2: Unit_Price | Y2: Payment_Method | Z2: Region | AA2: Customer_Segment | AB2: Customer_Since | AC2: Total_Amount | AE2: Transaction_ID | AF2: Date | AG2: Customer_ID | AH2: Customer_Name | AI2: Product_ID | AJ2: Product_Name | AK2: Category | AL2: Quantity | AM2: Unit_Price | AN2: Payment_Method | AO2: Region | AP2: Customer_Segment | AQ2: Customer_Since | AR2: Total_Amount | AT2: Transaction_ID | AU2: Date | AV2: Customer_ID | AW2: Customer_Name | AX2: Product_ID | AY2: Product_Name | AZ2: Category | BA2: Quantity | BB2: Unit_Price | BC2: Payment_Method | BD2: Region | BE2: Customer_Segment | BF2: Customer_Since | BG2: Total_Amount
A3: {=_xlfn._xlws.FILTER(Dataset!A2:N252,(Dataset!G2:G252="Electronics") * (Dataset!K2:K252="North"),"No Matching Records")} -> TRX0230 | B3: 45409 | C3: CUST027 | D3: George Adams | E3: P001 | F3: Laptop | G3: Electronics | H3: 1 | I3: 899.99 | J3: Debit Card | K3: North | L3: Standard | M3: 44920 | N3: 899.99 | P3: {=_xlfn._xlws.FILTER(Dataset!A2:N252,Dataset!N2:N252 > 1500,"No Matching Records")} -> TRX0135 | Q3: 45405 | R3: CUST009 | S3: Robert Thomas | T3: P001 | U3: Laptop | V3: Electronics | W3: 3 | X3: 899.99 | Y3: PayPal | Z3: East | AA3: Standard | AB3: 45299 | AC3: 2699.97 | AE3: {=_xlfn._xlws.FILTER(Dataset!A2:N252,Dataset!J2:J252="Cash","No Matching Records")} -> TRX0155 | AF3: 45393 | AG3: CUST023 | AH3: Paul Baker | AI3: P009 | AJ3: Monitor | AK3: Electronics | AL3: 3 | AM3: 249.99 | AN3: Cash | AO3: Central | AP3: Basic | AQ3: 44425 | AR3: 749.97 | AT3: {=_xlfn._xlws.FILTER(Dataset!A2:N252,(Dataset!J2:J252="Credit Card") * (Dataset!L2:L252="Premium"),"No records Found")} -> TRX0023 | AU3: 45396 | AV3: CUST013 | AW3: Joseph Jackson | AX3: P009 | AY3: Monitor | AZ3: Electronics | BA3: 3 | BB3: 249.99 | BC3: Credit Card | BD3: Central | BE3: Premium | BF3: 44575 | BG3: 749.97
A4: TRX0134 | B4: 45410 | C4: CUST010 | D4: Maria Garcia | E4: P002 | F4: Smartphone | G4: Electronics | H4: 2 | I4: 699.99 | J4: Cash | K4: North | L4: Basic | M4: 44781 | N4: 1399.98 | P4: TRX0191 | Q4: 45409 | R4: CUST038 | S4: Michelle Rogers | T4: P002 | U4: Smartphone | V4: Electronics | W4: 3 | X4: 699.99 | Y4: Credit Card | Z4: West | AA4: Basic | AB4: 44577 | AC4: 2099.97 | AE4: TRX0043 | AF4: 45400 | AG4: CUST046 | AH4: Kathleen Bennett | AI4: P005 | AJ4: Blender | AK4: Appliances | AL4: 3 | AM4: 59.99 | AN4: Cash | AO4: North | AP4: Premium | AQ4: 45114 | AR4: 179.97 | AT4: TRX0212 | AU4: 45400 | AV4: CUST003 | AW4: Michael Brown | AX4: P008 | AY4: Bookshelf | AZ4: Furniture | BA4: 5 | BB4: 149.99 | BC4: Credit Card | BD4: North | BE4: Premium | BF4: 45295 | BG4: 749.95
A5: TRX0222 | B5: 45410 | C5: CUST048 | D5: Virginia Sanders | E5: P009 | F5: Monitor | G5: Electronics | H5: 3 | I5: 249.99 | J5: Credit Card | K5: North | L5: Premium | M5: 45224 | N5: 749.97 | P5: TRX0122 | Q5: 45410 | R5: CUST025 | S5: Mark Carter | T5: P001 | U5: Laptop | V5: Electronics | W5: 4 | X5: 899.99 | Y5: Credit Card | Z5: West | AA5: Standard | AB5: 45327 | AC5: 3599.96 | AE5: TRX0092 | AF5: 45403 | AG5: CUST024 | AH5: Dorothy Nelson | AI5: P005 | AJ5: Blender | AK5: Appliances | AL5: 2 | AM5: 59.99 | AN5: Cash | AO5: West | AP5: Standard | AQ5: 44746 | AR5: 119.98 | AT5: TRX0222 | AU5: 45410 | AV5: CUST048 | AW5: Virginia Sanders | AX5: P009 | AY5: Monitor | AZ5: Electronics | BA5: 3 | BB5: 249.99 | BC5: Credit Card | BD5: North | BE5: Premium | BF5: 45224 | BG5: 749.97
A6: TRX0204 | B6: 45415 | C6: CUST044 | D6: Cynthia Price | E6: P009 | F6: Monitor | G6: Electronics | H6: 4 | I6: 249.99 | J6: PayPal | K6: North | L6: Standard | M6: 44468 | N6: 999.96 | P6: TRX0231 | Q6: 45412 | R6: CUST018 | S6: Barbara Young | T6: P002 | U6: Smartphone | V6: Electronics | W6: 5 | X6: 699.99 | Y6: Cash | Z6: West | AA6: Basic | AB6: 45167 | AC6: 3499.95 | AE6: TRX0185 | AF6: 45408 | AG6: CUST026 | AH6: Karen Hill | AI6: P005 | AJ6: Blender | AK6: Appliances | AL6: 3 | AM6: 59.99 | AN6: Cash | AO6: West | AP6: Premium | AQ6: 45207 | AR6: 179.97 | AT6: TRX0130 | AU6: 45430 | AV6: CUST002 | AW6: Emma Wilson | AX6: P008 | AY6: Bookshelf | AZ6: Furniture | BA6: 3 | BB6: 149.99 | BC6: Credit Card | BD6: West | BE6: Premium | BF6: 45068 | BG6: 449.97
A7: TRX0004 | B7: 45424 | C7: CUST012 | D7: Patricia Moore | E7: P010 | F7: Keyboard | G7: Electronics | H7: 5 | I7: 89.99 | J7: Cash | K7: North | L7: Premium | M7: 44919 | N7: 449.95 | P7: TRX0239 | Q7: 45413 | R7: CUST012 | S7: Patricia Moore | T7: P002 | U7: Smartphone | V7: Electronics | W7: 4 | X7: 699.99 | Y7: Cash | Z7: East | AA7: Standard | AB7: 44409 | AC7: 2799.96 | AE7: TRX0246 | AF7: 45408 | AG7: CUST041 | AH7: Peter Richardson | AI7: P008 | AJ7: Bookshelf | AK7: Furniture | AL7: 3 | AM7: 149.99 | AN7: Cash | AO7: North | AP7: Premium | AQ7: 44806 | AR7: 449.97 | AT7: TRX0041 | AU7: 45432 | AV7: CUST021 | AW7: Kevin Scott | AX7: P001 | AY7: Laptop | AZ7: Electronics | BA7: 1 | BB7: 899.99 | BC7: Credit Card | BD7: West | BE7: Premium | BF7: 44578 | BG7: 899.99
A8: TRX0117 | B8: 45444 | C8: CUST017 | D8: Charles Allen | E8: P010 | F8: Keyboard | G8: Electronics | H8: 1 | I8: 89.99 | J8: Cash | K8: North | L8: Basic | M8: 45141 | N8: 89.99 | P8: TRX0015 | Q8: 45440 | R8: CUST008 | S8: Jennifer Taylor | T8: P002 | U8: Smartphone | V8: Electronics | W8: 5 | X8: 699.99 | Y8: PayPal | Z8: West | AA8: Standard | AB8: 44407 | AC8: 3499.95 | AE8: TRX0134 | AF8: 45410 | AG8: CUST010 | AH8: Maria Garcia | AI8: P002 | AJ8: Smartphone | AK8: Electronics | AL8: 2 | AM8: 699.99 | AN8: Cash | AO8: North | AP8: Basic | AQ8: 44781 | AR8: 1399.98 | AT8: TRX0245 | AU8: 45438 | AV8: CUST031 | AW8: Steven Turner | AX8: P006 | AY8: Office Chair | AZ8: Furniture | BA8: 3 | BB8: 199.99 | BC8: Credit Card | BD8: North | BE8: Premium | BF8: 45292 | BG8: 599.97
A9: TRX0114 | B9: 45481 | C9: CUST018 | D9: Barbara Young | E9: P010 | F9: Keyboard | G9: Electronics | H9: 5 | I9: 89.99 | J9: Debit Card | K9: North | L9: Premium | M9: 45161 | N9: 449.95 | P9: TRX0154 | Q9: 45459 | R9: CUST023 | S9: Paul Baker | T9: P001 | U9: Laptop | V9: Electronics | W9: 5 | X9: 899.99 | Y9: Credit Card | Z9: South | AA9: Standard | AB9: 44974 | AC9: 4499.95 | AE9: TRX0231 | AF9: 45412 | AG9: CUST018 | AH9: Barbara Young | AI9: P002 | AJ9: Smartphone | AK9: Electronics | AL9: 5 | AM9: 699.99 | AN9: Cash | AO9: West | AP9: Basic | AQ9: 45167 | AR9: 3499.95 | AT9: TRX0115 | AU9: 45459 | AV9: CUST012 | AW9: Patricia Moore | AX9: P010 | AY9: Keyboard | AZ9: Electronics | BA9: 2 | BB9: 89.99 | BC9: Credit Card | BD9: South | BE9: Premium | BF9: 44471 | BG9: 179.98
A10: TRX0080 | B10: 45500 | C10: CUST018 | D10: Barbara Young | E10: P009 | F10: Monitor | G10: Electronics | H10: 2 | I10: 249.99 | J10: Cash | K10: North | L10: Premium | M10: 45164 | N10: 499.98 | P10: TRX0044 | Q10: 45459 | R10: CUST029 | S10: Edward Mitchell | T10: P001 | U10: Laptop | V10: Electronics | W10: 5 | X10: 899.99 | Y10: PayPal | Z10: East | AA10: Premium | AB10: 45278 | AC10: 4499.95 | AE10: TRX0239 | AF10: 45413 | AG10: CUST012 | AH10: Patricia Moore | AI10: P002 | AJ10: Smartphone | AK10: Electronics | AL10: 4 | AM10: 699.99 | AN10: Cash | AO10: East | AP10: Standard | AQ10: 44409 | AR10: 2799.96 | AT10: TRX0184 | AU10: 45471 | AV10: CUST046 | AW10: Kathleen Bennett | AX10: P002 | AY10: Smartphone | AZ10: Electronics | BA10: 3 | BB10: 699.99 | BC10: Credit Card | BD10: East | BE10: Premium | BF10: 45102 | BG10: 2099.97
A11: TRX0217 | B11: 45503 | C11: CUST025 | D11: Mark Carter | E11: P002 | F11: Smartphone | G11: Electronics | H11: 2 | I11: 699.99 | J11: Credit Card | K11: North | L11: Premium | M11: 44999 | N11: 1399.98 | P11: TRX0184 | Q11: 45471 | R11: CUST046 | S11: Kathleen Bennett | T11: P002 | U11: Smartphone | V11: Electronics | W11: 3 | X11: 699.99 | Y11: Credit Card | Z11: East | AA11: Premium | AB11: 45102 | AC11: 2099.97 | AE11: TRX0242 | AF11: 45416 | AG11: CUST025 | AH11: Mark Carter | AI11: P007 | AJ11: Desk | AK11: Furniture | AL11: 4 | AM11: 299.99 | AN11: Cash | AO11: West | AP11: Premium | AQ11: 44716 | AR11: 1199.96 | AT11: TRX0104 | AU11: 45471 | AV11: CUST012 | AW11: Patricia Moore | AX11: P001 | AY11: Laptop | AZ11: Electronics | BA11: 4 | BB11: 899.99 | BC11: Credit Card | BD11: East | BE11: Premium | BF11: 44993 | BG11: 3599.96
A12: TRX0101 | B12: 45513 | C12: CUST010 | D12: Maria Garcia | E12: P010 | F12: Keyboard | G12: Electronics | H12: 1 | I12: 89.99 | J12: Credit Card | K12: North | L12: Standard | M12: 45393 | N12: 89.99 | P12: TRX0104 | Q12: 45471 | R12: CUST012 | S12: Patricia Moore | T12: P001 | U12: Laptop | V12: Electronics | W12: 4 | X12: 899.99 | Y12: Credit Card | Z12: East | AA12: Premium | AB12: 44993 | AC12: 3599.96 | AE12: TRX0004 | AF12: 45424 | AG12: CUST012 | AH12: Patricia Moore | AI12: P010 | AJ12: Keyboard | AK12: Electronics | AL12: 5 | AM12: 89.99 | AN12: Cash | AO12: North | AP12: Premium | AQ12: 44919 | AR12: 449.95 | AT12: TRX0141 | AU12: 45484 | AV12: CUST033 | AW12: Frank Torres | AX12: P007 | AY12: Desk | AZ12: Furniture | BA12: 1 | BB12: 299.99 | BC12: Credit Card | BD12: North | BE12: Premium | BF12: 44891 | BG12: 299.99
A13: TRX0098 | B13: 45517 | C13: CUST026 | D13: Karen Hill | E13: P009 | F13: Monitor | G13: Electronics | H13: 3 | I13: 249.99 | J13: PayPal | K13: North | L13: Premium | M13: 44465 | N13: 749.97 | P13: TRX0244 | Q13: 45497 | R13: CUST013 | S13: Joseph Jackson | T13: P001 | U13: Laptop | V13: Electronics | W13: 5 | X13: 899.99 | Y13: Debit Card | Z13: South | AA13: Standard | AB13: 44899 | AC13: 4499.95 | AE13: TRX0029 | AF13: 45427 | AG13: CUST017 | AH13: Charles Allen | AI13: P006 | AJ13: Office Chair | AK13: Furniture | AL13: 5 | AM13: 199.99 | AN13: Cash | AO13: South | AP13: Standard | AQ13: 44412 | AR13: 999.95 | AT13: TRX0217 | AU13: 45503 | AV13: CUST025 | AW13: Mark Carter | AX13: P002 | AY13: Smartphone | AZ13: Electronics | BA13: 2 | BB13: 699.99 | BC13: Credit Card | BD13: North | BE13: Premium | BF13: 44999 | BG13: 1399.98
A14: TRX0248 | B14: 45534 | C14: CUST032 | D14: Sandra Phillips | E14: P002 | F14: Smartphone | G14: Electronics | H14: 2 | I14: 699.99 | J14: Credit Card | K14: North | L14: Premium | M14: 44421 | N14: 1399.98 | P14: TRX0249 | Q14: 45504 | R14: CUST030 | S14: Helen Roberts | T14: P001 | U14: Laptop | V14: Electronics | W14: 4 | X14: 899.99 | Y14: Debit Card | Z14: South | AA14: Standard | AB14: 44523 | AC14: 3599.96 | AE14: TRX0021 | AF14: 45435 | AG14: CUST006 | AH14: Lisa Anderson | AI14: P004 | AJ14: Coffee Maker | AK14: Appliances | AL14: 3 | AM14: 79.99 | AN14: Cash | AO14: South | AP14: Basic | AQ14: 45046 | AR14: 239.97 | AT14: TRX0248 | AU14: 45534 | AV14: CUST032 | AW14: Sandra Phillips | AX14: P002 | AY14: Smartphone | AZ14: Electronics | BA14: 2 | BB14: 699.99 | BC14: Credit Card | BD14: North | BE14: Premium | BF14: 44421 | BG14: 1399.98
A15: TRX0074 | B15: 45537 | C15: CUST023 | D15: Paul Baker | E15: P009 | F15: Monitor | G15: Electronics | H15: 1 | I15: 249.99 | J15: Debit Card | K15: North | L15: Premium | M15: 45332 | N15: 249.99 | P15: TRX0132 | Q15: 45523 | R15: CUST047 | S15: Gerald Murphy | T15: P001 | U15: Laptop | V15: Electronics | W15: 5 | X15: 899.99 | Y15: Debit Card | Z15: East | AA15: Basic | AB15: 44526 | AC15: 4499.95 | AE15: TRX0042 | AF15: 45443 | AG15: CUST019 | AH15: Daniel King | AI15: P004 | AJ15: Coffee Maker | AK15: Appliances | AL15: 1 | AM15: 79.99 | AN15: Cash | AO15: North | AP15: Standard | AQ15: 44917 | AR15: 79.99 | AT15: TRX0099 | AU15: 45537 | AV15: CUST034 | AW15: Carol Evans | AX15: P009 | AY15: Monitor | AZ15: Electronics | BA15: 1 | BB15: 249.99 | BC15: Credit Card | BD15: West | BE15: Premium | BF15: 44685 | BG15: 249.99
... A31: TRX0107 | B31: 45671 | C31: CUST030 | D31: Helen Roberts | E31: P003 | F31: Headphones | G31: Electronics | H31: 2 | I31: 149.99 | J31: Cash | K31: North | L31: Standard | M31: 44913 | N31: 299.98 | P31: TRX0179 | Q31: 45707 | R31: CUST029 | S31: Edward Mitchell | T31: P002 | U31: Smartphone | V31: Electronics | W31: 5 | X31: 699.99 | Y31: PayPal | Z31: South | AA31: Premium | AB31: 45352 | AC31: 3499.95 | AE31: TRX0228 | AF31: 45500 | AG31: CUST019 | AH31: Daniel King | AI31: P007 | AJ31: Desk | AK31: Furniture | AL31: 1 | AM31: 299.99 | AN31: Cash | AO31: South | AP31: Basic | AQ31: 44982 | AR31: 299.99 | AT31: TRX0019 | AU31: 45739 | AV31: CUST023 | AW31: Paul Baker | AX31: P007 | AY31: Desk | AZ31: Furniture | BA31: 3 | BB31: 299.99 | BC31: Credit Card | BD31: West | BE31: Premium | BF31: 45234 | BG31: 899.97
A32: TRX0047 | B32: 45711 | C32: CUST042 | D32: Ruth Brooks | E32: P002 | F32: Smartphone | G32: Electronics | H32: 1 | I32: 699.99 | J32: Cash | K32: North | L32: Premium | M32: 44583 | N32: 699.99 | P32: TRX0214 | Q32: 45708 | R32: CUST018 | S32: Barbara Young | T32: P001 | U32: Laptop | V32: Electronics | W32: 3 | X32: 899.99 | Y32: Cash | Z32: East | AA32: Standard | AB32: 44613 | AC32: 2699.97 | AE32: TRX0002 | AF32: 45501 | AG32: CUST019 | AH32: Daniel King | AI32: P007 | AJ32: Desk | AK32: Furniture | AL32: 3 | AM32: 299.99 | AN32: Cash | AO32: Central | AP32: Basic | AQ32: 44732 | AR32: 899.97
A33: TRX0038 | B33: 45726 | C33: CUST035 | D33: Harry Morgan | E33: P009 | F33: Monitor | G33: Electronics | H33: 1 | I33: 249.99 | J33: Cash | K33: North | L33: Standard | M33: 45117 | N33: 249.99 | P33: TRX0226 | Q33: 45720 | R33: CUST039 | S33: Lawrence Reed | T33: P002 | U33: Smartphone | V33: Electronics | W33: 5 | X33: 699.99 | Y33: Debit Card | Z33: East | AA33: Premium | AB33: 45161 | AC33: 3499.95 | AE33: TRX0247 | AF33: 45517 | AG33: CUST046 | AH33: Kathleen Bennett | AI33: P006 | AJ33: Office Chair | AK33: Furniture | AL33: 4 | AM33: 199.99 | AN33: Cash | AO33: North | AP33: Standard | AQ33: 44458 | AR33: 799.96
A34: TRX0124 | B34: 45737 | C34: CUST040 | D34: Sharon Butler | E34: P001 | F34: Laptop | G34: Electronics | H34: 3 | I34: 899.99 | J34: Debit Card | K34: North | L34: Premium | M34: 44876 | N34: 2699.97 | P34: TRX0016 | Q34: 45724 | R34: CUST035 | S34: Harry Morgan | T34: P001 | U34: Laptop | V34: Electronics | W34: 5 | X34: 899.99 | Y34: PayPal | Z34: East | AA34: Premium | AB34: 45389 | AC34: 4499.95 | AE34: TRX0027 | AF34: 45519 | AG34: CUST028 | AH34: Betty Campbell | AI34: P006 | AJ34: Office Chair | AK34: Furniture | AL34: 5 | AM34: 199.99 | AN34: Cash | AO34: North | AP34: Premium | AQ34: 44991 | AR34: 999.95
A35: TRX0013 | B35: 45737 | C35: CUST024 | D35: Dorothy Nelson | E35: P001 | F35: Laptop | G35: Electronics | H35: 3 | I35: 899.99 | J35: PayPal | K35: North | L35: Basic | M35: 44975 | N35: 2699.97 | P35: TRX0124 | Q35: 45737 | R35: CUST040 | S35: Sharon Butler | T35: P001 | U35: Laptop | V35: Electronics | W35: 3 | X35: 899.99 | Y35: Debit Card | Z35: North | AA35: Premium | AB35: 44876 | AC35: 2699.97 | AE35: TRX0140 | AF35: 45522 | AG35: CUST025 | AH35: Mark Carter | AI35: P010 | AJ35: Keyboard | AK35: Electronics | AL35: 2 | AM35: 89.99 | AN35: Cash | AO35: East | AP35: Premium | AQ35: 44972 | AR35: 179.98
A36: TRX0068 | B36: 45748 | C36: CUST044 | D36: Cynthia Price | E36: P002 | F36: Smartphone | G36: Electronics | H36: 2 | I36: 699.99 | J36: PayPal | K36: North | L36: Standard | M36: 44618 | N36: 1399.98 | P36: TRX0013 | Q36: 45737 | R36: CUST024 | S36: Dorothy Nelson | T36: P001 | U36: Laptop | V36: Electronics | W36: 3 | X36: 899.99 | Y36: PayPal | Z36: North | AA36: Basic | AB36: 44975 | AC36: 2699.97 | AE36: TRX0001 | AF36: 45528 | AG36: CUST039 | AH36: Lawrence Reed | AI36: P004 | AJ36: Coffee Maker | AK36: Appliances | AL36: 3 | AM36: 79.99 | AN36: Cash | AO36: Central | AP36: Premium | AQ36: 44779 | AR36: 239.97
A37: TRX0120 | B37: 45758 | C37: CUST045 | D37: Douglas Watson | E37: P002 | F37: Smartphone | G37: Electronics | H37: 3 | I37: 699.99 | J37: PayPal | K37: North | L37: Basic | M37: 44909 | N37: 2099.97 | P37: TRX0144 | Q37: 45749 | R37: CUST029 | S37: Edward Mitchell | T37: P001 | U37: Laptop | V37: Electronics | W37: 3 | X37: 899.99 | Y37: Cash | Z37: Central | AA37: Standard | AB37: 44953 | AC37: 2699.97 | AE37: TRX0037 | AF37: 45528 | AG37: CUST035 | AH37: Harry Morgan | AI37: P009 | AJ37: Monitor | AK37: Electronics | AL37: 2 | AM37: 249.99 | AN37: Cash | AO37: South | AP37: Standard | AQ37: 44572 | AR37: 499.98
A38: TRX0064 | B38: 45758 | C38: CUST031 | D38: Steven Turner | E38: P010 | F38: Keyboard | G38: Electronics | H38: 3 | I38: 89.99 | J38: Debit Card | K38: North | L38: Premium | M38: 44878 | N38: 269.97 | P38: TRX0120 | Q38: 45758 | R38: CUST045 | S38: Douglas Watson | T38: P002 | U38: Smartphone | V38: Electronics | W38: 3 | X38: 699.99 | Y38: PayPal | Z38: North | AA38: Basic | AB38: 44909 | AC38: 2099.97 | AE38: TRX0058 | AF38: 45532 | AG38: CUST047 | AH38: Gerald Murphy | AI38: P002 | AJ38: Smartphone | AK38: Electronics | AL38: 1 | AM38: 699.99 | AN38: Cash | AO38: Central | AP38: Premium | AQ38: 44497 | AR38: 699.99
AE39: TRX0170 | AF39: 45532 | AG39: CUST034 | AH39: Carol Evans | AI39: P003 | AJ39: Headphones | AK39: Electronics | AL39: 3 | AM39: 149.99 | AN39: Cash | AO39: West | AP39: Premium | AQ39: 45212 | AR39: 449.97
AE40: TRX0112 | AF40: 45544 | AG40: CUST008 | AH40: Jennifer Taylor | AI40: P004 | AJ40: Coffee Maker | AK40: Appliances | AL40: 4 | AM40: 79.99 | AN40: Cash | AO40: North | AP40: Basic | AQ40: 44530 | AR40: 319.96
AE41: TRX0161 | AF41: 45545 | AG41: CUST017 | AH41: Charles Allen | AI41: P004 | AJ41: Coffee Maker | AK41: Appliances | AL41: 1 | AM41: 79.99 | AN41: Cash | AO41: West | AP41: Basic | AQ41: 44693 | AR41: 79.99
AE42: TRX0005 | AF42: 45550 | AG42: CUST042 | AH42: Ruth Brooks | AI42: P003 | AJ42: Headphones | AK42: Electronics | AL42: 4 | AM42: 149.99 | AN42: Cash | AO42: North | AP42: Basic | AQ42: 44909 | AR42: 599.96
AE43: TRX0174 | AF43: 45566 | AG43: CUST003 | AH43: Michael Brown | AI43: P007 | AJ43: Desk | AK43: Furniture | AL43: 4 | AM43: 299.99 | AN43: Cash | AO43: Central | AP43: Premium | AQ43: 44460 | AR43: 1199.96
AE44: TRX0173 | AF44: 45581 | AG44: CUST018 | AH44: Barbara Young | AI44: P002 | AJ44: Smartphone | AK44: Electronics | AL44: 5 | AM44: 699.99 | AN44: Cash | AO44: East | AP44: Standard | AQ44: 45008 | AR44: 3499.95
AE45: TRX0009 | AF45: 45588 | AG45: CUST004 | AH45: Sarah Davis | AI45: P002 | AJ45: Smartphone | AK45: Electronics | AL45: 2 | AM45: 699.99 | AN45: Cash | AO45: Central | AP45: Basic | AQ45: 44992 | AR45: 1399.98
AE46: TRX0167 | AF46: 45589 | AG46: CUST028 | AH46: Betty Campbell | AI46: P002 | AJ46: Smartphone | AK46: Electronics | AL46: 5 | AM46: 699.99 | AN46: Cash | AO46: North | AP46: Premium | AQ46: 44635 | AR46: 3499.95
AE47: TRX0035 | AF47: 45607 | AG47: CUST041 | AH47: Peter Richardson | AI47: P003 | AJ47: Headphones | AK47: Electronics | AL47: 3 | AM47: 149.99 | AN47: Cash | AO47: North | AP47: Basic | AQ47: 44769 | AR47: 449.97
AE48: TRX0073 | AF48: 45613 | AG48: CUST032 | AH48: Sandra Phillips | AI48: P008 | AJ48: Bookshelf | AK48: Furniture | AL48: 5 | AM48: 149.99 | AN48: Cash | AO48: North | AP48: Basic | AQ48: 44869 | AR48: 749.95
AE49: TRX0206 | AF49: 45623 | AG49: CUST014 | AH49: Linda Martin | AI49: P008 | AJ49: Bookshelf | AK49: Furniture | AL49: 2 | AM49: 149.99 | AN49: Cash | AO49: South | AP49: Standard | AQ49: 45101 | AR49: 299.98
AE50: TRX0045 | AF50: 45627 | AG50: CUST021 | AH50: Kevin Scott | AI50: P007 | AJ50: Desk | AK50: Furniture | AL50: 3 | AM50: 299.99 | AN50: Cash | AO50: South | AP50: Premium | AQ50: 44659 | AR50: 899.97
... AE78: TRX0144 | AF78: 45749 | AG78: CUST029 | AH78: Edward Mitchell | AI78: P001 | AJ78: Laptop | AK78: Electronics | AL78: 3 | AM78: 899.99 | AN78: Cash | AO78: Central | AP78: Standard | AQ78: 44953 | AR78: 2699.97
A82: Unique Customer | D82: Total Spend | F82: Transaction Count | H82: Average Order Value | J82: Label high value customer
A83: {=_xlfn.UNIQUE(Dataset!D2:D252)} -> Paul Baker | D83: =SUMIF(Dataset!D2:D252,'Analysis & Calculation'!A83,Dataset!N2:N252) -> 8309.74 | F83: =COUNTIF(Dataset!D2:D252,'Analysis & Calculation'!A83) -> 8 | H83: =AVERAGEIF(Dataset!D2:D252,'Analysis & Calculation'!A83,Dataset!N2:N252) -> 1038.7175 | J83: =IF(D83>5000,"VIP Customer","Standard Customer") -> VIP Customer
A84: Joseph Jackson | D84: =SUMIF(Dataset!D3:D253,'Analysis & Calculation'!A84,Dataset!N3:N253) -> 6949.84 | F84: =COUNTIF(Dataset!D3:D253,'Analysis & Calculation'!A84) -> 5 | H84: =AVERAGEIF(Dataset!D3:D253,'Analysis & Calculation'!A84,Dataset!N3:N253) -> 1389.968 | J84: =IF(D84>5000,"VIP Customer","Standard Customer") -> VIP Customer
A85: Kevin Scott | D85: =SUMIF(Dataset!D4:D254,'Analysis & Calculation'!A85,Dataset!N4:N254) -> 3259.87 | F85: =COUNTIF(Dataset!D4:D254,'Analysis & Calculation'!A85) -> 6 | H85: =AVERAGEIF(Dataset!D4:D254,'Analysis & Calculation'!A85,Dataset!N4:N254) -> 543.31167 | J85: =IF(D85>5000,"VIP Customer","Standard Customer") -> Standard Customer
...

Sheet Data Visualisation
A2: Category wise total customer | F2: Category wise total quantity | K2: Category wise total amount and their payment method | P2: Region wise Payment method,category and ttheir total amount | W2: Regioin wise product name,category and their total amount
A3: Category | B3: Count of Customer_ID | F3: Category | G3: Sum of Quantity | K3: Payment_Method | L3: Category | M3: Sum of Total_Amount | P3: Region | Q3: Payment_Method | R3: Category | S3: Sum of Total_Amount | W3: Product_Name | X3: Region | Y3: Category | Z3: Sum of Total_Amount
A4: Appliances | B4: 43 | F4: Appliances | G4: 126 | K4: Cash | L4: Appliances | M4: 3239.51 | P4: Central | Q4: Cash | R4: Appliances | S4: 419.94 | W4: Blender | X4: Central | Y4: Appliances | Z4: 959.84
A5: Electronics | B5: 131 | F5: Electronics | G5: 395 | L5: Electronics | M5: 35889.14 | R5: Electronics | S5: 8299.79 | X5: Central Total | Z5: 959.84
A6: Furniture | B6: 76 | F6: Furniture | G6: 232 | L6: Furniture | M6: 18299.14 | R6: Furniture | S6: 5199.74 | X6: East | Y6: Appliances | Z6: 1199.8
A7: Grand Total | B7: 250 | F7: Grand Total | G7: 753 | K7: Cash Total | M7: 57427.79 | Q7: Cash Total | S7: 13919.47 | X7: East Total | Z7: 1199.8
K8: Credit Card | L8: Appliances | M8: 1419.79 | Q8: Credit Card | R8: Appliances | S8: 619.91 | X8: North | Y8: Appliances | Z8: 479.92
L9: Electronics | M9: 45728.8 | R9: Electronics | S9: 6899.83 | X9: North Total | Z9: 479.92
L10: Furniture | M10: 14299.37 | R10: Furniture | S10: 3349.85 | X10: South | Y10: Appliances | Z10: 779.87
K11: Credit Card Total | M11: 61447.96 | Q11: Credit Card Total | S11: 10869.59 | X11: South Total | Z11: 779.87
K12: Debit Card | L12: Appliances | M12: 2699.59 | Q12: Debit Card | R12: Appliances | S12: 879.87 | X12: West | Y12: Appliances | Z12: 1799.7
L13: Electronics | M13: 40519.15 | R13: Electronics | S13: 4889.87 | X13: West Total | Z13: 1799.7
L14: Furniture | M14: 8899.57 | R14: Furniture | S14: 2899.89 | W14: Blender Total | Z14: 5219.13
K15: Debit Card Total | M15: 52118.31 | Q15: Debit Card Total | S15: 8669.63 | W15: Bookshelf | X15: Central | Y15: Furniture | Z15: 4799.68
K16: PayPal | L16: Appliances | M16: 979.85 | Q16: PayPal | R16: Appliances | S16: 79.99 | X16: Central Total | Z16: 4799.68
L17: Electronics | M17: 49618.96 | R17: Electronics | S17: 4799.84 | X17: East | Y17: Furniture | Z17: 1799.88
L18: Furniture | M18: 7599.6 | R18: Furniture | S18: 2949.82 | X18: East Total | Z18: 1799.88
K19: PayPal Total | M19: 58198.41 | Q19: PayPal Total | S19: 7829.65 | X19: North | Y19: Furniture | Z19: 4949.67
K20: Grand Total | M20: 229192.47 | P20: Central Total | S20: 41288.34 | X20: North Total | Z20: 4949.67
P21: East | Q21: Cash | R21: Appliances | S21: 479.93 | X21: South | Y21: Furniture | Z21: 1349.91
R22: Electronics | S22: 10429.81 | X22: South Total | Z22: 1349.91
R23: Furniture | S23: 899.96 | X23: West | Y23: Furniture | Z23: 2399.84
Q24: Cash Total | S24: 11809.7 | X24: West Total | Z24: 2399.84
Q25: Credit Card | R25: Electronics | S25: 8749.77 | W25: Bookshelf Total | Z25: 15298.98
R26: Furniture | S26: 1349.94 | W26: Coffee Maker | X26: Central | Y26: Appliances | Z26: 1039.87
Q27: Credit Card Total | S27: 10099.71 | X27: Central Total | Z27: 1039.87
Q28: Debit Card | R28: Appliances | S28: 1339.8 | X28: East | Y28: Appliances | Z28: 1039.87
R29: Electronics | S29: 14769.76 | X29: East Total | Z29: 1039.87
R30: Furniture | S30: 2049.9 | X30: North | Y30: Appliances | Z30: 639.92
Q31: Debit Card Total | S31: 18159.46 | X31: North Total | Z31: 639.92
Q32: PayPal | R32: Appliances | S32: 419.94 | X32: South | Y32: Appliances | Z32: 319.96
R33: Electronics | S33: 16699.67 | X33: South Total | Z33: 319.96
R34: Furniture | S34: 2099.91 | X34: West | Y34: Appliances | Z34: 79.99
Q35: PayPal Total | S35: 19219.52 | X35: West Total | Z35: 79.99
P36: East Total | S36: 59288.39 | W36: Coffee Maker Total | Z36: 3119.61
P37: North | Q37: Cash | R37: Appliances | S37: 699.9 | W37: Desk | X37: Central | Y37: Furniture | Z37: 5999.8
R38: Electronics | S38: 12139.69 | X38: Central Total | Z38: 5999.8
R39: Furniture | S39: 3999.78 | X39: East | Y39: Furniture | Z39: 3599.88
Q40: Cash Total | S40: 16839.37 | X40: East Total | Z40: 3599.88
Q41: Credit Card | R41: Appliances | S41: 419.94 | X41: North | Y41: Furniture | Z41: 2099.93
...
